<?xml version="1.0" ?>
<!-- =================================================================================== -->
<!-- |    This document was autogenerated by xacro from robots/aida.urdf.xacro         | -->
<!-- |    EDITING THIS FILE BY HAND IS NOT RECOMMENDED                                 | -->
<!-- =================================================================================== -->
<robot name="aida" xmlns:xacro="http://www.ros.org/wiki/xacro">
  <gazebo reference="left_rear_calf">
    <material>Gazebo/Orange</material>
  </gazebo>
  <gazebo reference="right_rear_calf">
    <material>Gazebo/Orange</material>
  </gazebo>
  <gazebo reference="left_front_calf">
    <material>Gazebo/Orange</material>
  </gazebo>
  <gazebo reference="right_front_calf">
    <material>Gazebo/Orange</material>
  </gazebo>
  <gazebo reference="left_rear_shoulder">
    <material>Gazebo/Orange</material>
  </gazebo>
  <gazebo reference="right_rear_shoulder">
    <material>Gazebo/Orange</material>
  </gazebo>
  <gazebo reference="left_front_shoulder">
    <material>Gazebo/Orange</material>
  </gazebo>
  <gazebo reference="right_front_shoulder">
    <material>Gazebo/Orange</material>
  </gazebo>
  <gazebo reference="head">
    <material>Gazebo/Red</material>
  </gazebo>
  <gazebo>
    <plugin filename="libgazebo_ros_control.so" name="gazebo_ros_control">
      <robotNamespace>/aida</robotNamespace>
    </plugin>
  </gazebo>
  <!-- Sensor defintion ( TODO move to own file) -->
  <gazebo reference="right_rear_calf">
    <sensor name="right_rear_bumper" type="contact">
      <always_on>true</always_on>
      <update_rate>20.0</update_rate>
      <contact>
        <!-- weird gazebo naming convention  -->
        <collision>right_rear_calf_fixed_joint_lump__right_rear_foot_collision_1</collision>
      </contact>
      <plugin filename="libgazebo_ros_bumper.so" name="right_rear_foot_bumper_controller">
        <alwaysOn>true</alwaysOn>
        <updateRate>20.0</updateRate>
        <bumperTopicName>aida/bumper_right_rear_foot</bumperTopicName>
        <frameName>right_rear_foot</frameName>
      </plugin>
    </sensor>
  </gazebo>
  <gazebo reference="right_front_calf">
    <sensor name="right_front_bumper" type="contact">
      <always_on>true</always_on>
      <update_rate>20.0</update_rate>
      <contact>
        <!-- weird gazebo naming convention  -->
        <collision>right_front_calf_fixed_joint_lump__right_front_foot_collision_1</collision>
      </contact>
      <plugin filename="libgazebo_ros_bumper.so" name="right_front_foot_bumper_controller">
        <alwaysOn>true</alwaysOn>
        <updateRate>20.0</updateRate>
        <bumperTopicName>aida/bumper_right_front_foot</bumperTopicName>
        <frameName>right_front_foot</frameName>
      </plugin>
    </sensor>
  </gazebo>
  <gazebo reference="left_rear_calf">
    <sensor name="left_rear_bumper" type="contact">
      <always_on>true</always_on>
      <update_rate>20.0</update_rate>
      <contact>
        <!-- weird gazebo naming convention  -->
        <collision>left_rear_calf_fixed_joint_lump__left_rear_foot_collision_1</collision>
      </contact>
      <plugin filename="libgazebo_ros_bumper.so" name="left_rear_foot_bumper_controller">
        <alwaysOn>true</alwaysOn>
        <updateRate>20.0</updateRate>
        <bumperTopicName>aida/bumper_left_rear_foot</bumperTopicName>
        <frameName>left_rear_foot</frameName>
      </plugin>
    </sensor>
  </gazebo>
  <gazebo reference="left_front_calf">
    <sensor name="left_front_bumper" type="contact">
      <always_on>true</always_on>
      <update_rate>20.0</update_rate>
      <contact>
        <!-- weird gazebo naming convention  -->
        <collision>left_front_calf_fixed_joint_lump__left_front_foot_collision_1</collision>
      </contact>
      <plugin filename="libgazebo_ros_bumper.so" name="left_front_foot_bumper_controller">
        <alwaysOn>true</alwaysOn>
        <updateRate>20.0</updateRate>
        <bumperTopicName>aida/bumper_left_front_foot</bumperTopicName>
        <frameName>left_front_foot</frameName>
      </plugin>
    </sensor>
  </gazebo>
  <gazebo reference="right_rear_foot">
    <!-- kp and kd for rubber -->
    <kp>1000000.0</kp>
    <kd>100.0</kd>
    <mu1>1.5</mu1>
    <mu2>1.5</mu2>
    <fdir1>1 0 0</fdir1>
    <maxVel>1.0</maxVel>
    <minDepth>0.00</minDepth>
  </gazebo>
  <gazebo reference="right_front_foot">
    <!-- kp and kd for rubber -->
    <kp>1000000.0</kp>
    <kd>100.0</kd>
    <mu1>1.5</mu1>
    <mu2>1.5</mu2>
    <fdir1>1 0 0</fdir1>
    <maxVel>1.0</maxVel>
    <minDepth>0.00</minDepth>
  </gazebo>
  <gazebo reference="left_rear_foot">
    <!-- kp and kd for rubber -->
    <kp>1000000.0</kp>
    <kd>100.0</kd>
    <mu1>1.5</mu1>
    <mu2>1.5</mu2>
    <fdir1>1 0 0</fdir1>
    <maxVel>1.0</maxVel>
    <minDepth>0.00</minDepth>
  </gazebo>
  <gazebo reference="left_front_foot">
    <!-- kp and kd for rubber -->
    <kp>1000000.0</kp>
    <kd>100.0</kd>
    <mu1>1.5</mu1>
    <mu2>1.5</mu2>
    <fdir1>1 0 0</fdir1>
    <maxVel>1.0</maxVel>
    <minDepth>0.00</minDepth>
  </gazebo>
  <!--test_hinge lr="left" fr="front"/>
 <xacro:macro name="test_hinge" params="lr fr">
	<gazebo reference="aida">
        <plugin name="encoder_plugin" filename="libencoder_sensor_plugin.so"/>
    </gazebo>

 </xacro:macro>
-->
  <!-- Distance between legs left and right-->
  <!--Leg -->
  <!-- mass of the chassis -->
  <!-- mass of the shoulder  -->
  <!-- -->
  <!-- mass of the calf-->
  <!-- mass of the foot-->
  <!-- TODO add angles limits -->
  <!-- avoid collisions using a buffer, disregard once proper design. -->
  <link name="chassis">
    <collision>
      <origin rpy="0 0 0" xyz="0 0 0"/>
      <geometry>
        <box size="0.6 0.2 0.2"/>
      </geometry>
    </collision>
    <visual>
      <origin rpy="0 0 0" xyz="0 0 0"/>
      <geometry>
        <mesh filename="meshes/walking_base_v0/chassis.stl"/>
      </geometry>
    </visual>
    <inertial>
      <origin rpy="0 0 0" xyz="0 0 0"/>
      <mass value="10"/>
      <inertia ixx="0.0666666666667" ixy="0" ixz="0" iyy="0.333333333333" iyz="0" izz="0.333333333333"/>
    </inertial>
  </link>
  <!-- create the shoulder -->
  <!-- link name="${lr}_${fr}_shoulder_spring"> 
    <inertial> <origin xyz="0 0 0" rpy="0 0 0"/> <mass value="1"/> <inertia ixx="1.0" ixy="0.0" ixz="0.0" iyy="1.0" iyz="0.0" izz="1.0"/> </inertial>
    </link-->
  <link name="left_front_shoulder">
    <collision>
      <origin rpy="0 0 0" xyz="0 0 0"/>
      <geometry>
        <box size="0.1 0.1 0.1"/>
      </geometry>
    </collision>
    <visual>
      <origin rpy="0 1.570795 0" xyz="0 0 0"/>
      <geometry>
        <mesh filename="meshes/walking_base_v0/shoulder.stl">
                </mesh>
      </geometry>
      <material name="orange"/>
    </visual>
    <inertial>
      <origin rpy="0 0 0" xyz="0 0 0"/>
      <mass value="0.5"/>
      <inertia ixx="0.000833333333333" ixy="0" ixz="0" iyy="0.000833333333333" iyz="0" izz="0.000833333333333"/>
    </inertial>
  </link>
  <!-- create the thigh -->
  <link name="left_front_thigh_spring">
    <!-- elastic joint -->
    <inertial>
      <origin rpy="0 0 0" xyz="0 0 0"/>
      <mass value="1"/>
      <inertia ixx="1.0" ixy="0.0" ixz="0.0" iyy="1.0" iyz="0.0" izz="1.0"/>
    </inertial>
  </link>
  <link name="left_front_thigh">
    <collision>
      <origin rpy="0 1.570795 0" xyz="0.2 0 0"/>
      <geometry>
        <cylinder length="0.4" radius="0.04"/>
      </geometry>
    </collision>
    <visual>
      <origin rpy="0 1.570795 0" xyz="0 0 0"/>
      <geometry>
        <mesh filename="meshes/walking_base_v0/upper_leg.stl">
                </mesh>
      </geometry>
      <material name="orange"/>
    </visual>
    <inertial>
      <origin rpy="0 1.570795 0" xyz="0.2 0 0"/>
      <mass value="1.5"/>
      <inertia ixx="0.0206" ixy="0" ixz="0" iyy="0.0206" iyz="0" izz="0.0012"/>
    </inertial>
  </link>
  <!-- create the calf -->
  <link name="left_front_calf_spring">
    <inertial>
      <origin rpy="0 0 0" xyz="0 0 0"/>
      <mass value="1"/>
      <inertia ixx="1.0" ixy="0.0" ixz="0.0" iyy="1.0" iyz="0.0" izz="1.0"/>
    </inertial>
  </link>
  <link name="left_front_calf">
    <collision>
      <origin rpy="0 1.570795 0" xyz="0.15 0 0"/>
      <geometry>
        <cylinder length="0.3" radius="0.02"/>
      </geometry>
    </collision>
    <visual>
      <origin rpy="0 1.570795 0" xyz="0.15 0 0"/>
      <geometry>
        <mesh filename="meshes/walking_base_v0/lower_leg.stl">
                </mesh>
      </geometry>
    </visual>
    <inertial>
      <origin rpy="0 1.570795 0" xyz="0.15 0 0"/>
      <mass value="0.2"/>
      <inertia ixx="0.00152" ixy="0" ixz="0" iyy="0.00152" iyz="0" izz="4e-05"/>
    </inertial>
  </link>
  <!-- create the foot -->
  <link name="left_front_foot">
    <collision>
      <origin rpy="0 0 0" xyz="0 0 0"/>
      <geometry>
        <sphere radius="0.05"/>
      </geometry>
      <surface>
        <friction>
          <ode>
            <mu>1</mu>
            <mu2>1</mu2>
            <slip1>1.0</slip1>
            <slip2>1.0</slip2>
          </ode>
        </friction>
      </surface>
    </collision>
    <inertial>
      <origin rpy="0 0 0" xyz="0 0 0"/>
      <mass value="0.1"/>
      <inertia ixx="0.0001" ixy="0" ixz="0" iyy="0.0001" iyz="0" izz="0.0001"/>
    </inertial>
  </link>
  <!-- hinges -->
  <!-- A3 -->
  <!--joint name="${lr}_${fr}_elastic_joint_shoulder" type="revolute">
        <parent link="${lr}_${fr}_shoulder_spring"/>
        <child link="${lr}_${fr}_shoulder"/>
        <axis xyz="1 0 0" rpy="0 0 0">
        <dynamics>
            <spring_stiffness>1000.0</spring_stiffness>
            <spring_reference>0</spring_reference>
        </dynamics>
        </axis>
        <limit effort="1000" velocity="100" upper="${A1_upper_rad}" lower="${A1_lower_rad}"/> 
    </joint-->
  <joint name="left_front_shoulder_hinge" type="revolute">
    <parent link="chassis"/>
    <child link="left_front_shoulder"/>
    <origin rpy="0 0 0" xyz="0.25 0.15 0"/>
    <axis rpy="0 0 0" xyz="1 0 0"/>
    <limit effort="1000" lower="-0.174532777778" upper="0.7853975" velocity="100"/>
    <joint_properties damping="0.0" friction="0.0"/>
  </joint>
  <transmission name="left_front_shoulder_trans">
    <type>transmission_interface/SimpleTransmission</type>
    <joint name="left_front_shoulder_hinge">
      <hardwareInterface>hardware_interface/EffortJointInterface</hardwareInterface>
    </joint>
    <actuator name="left_front_shoulder_motor">
      <hardwareInterface>hardware_interface/EffortJointInterface</hardwareInterface>
      <mechanicalReduction>100</mechanicalReduction>
    </actuator>
  </transmission>
  <!-- A2 -->
  <joint name="left_front_thigh_hinge" type="revolute">
    <parent link="left_front_shoulder"/>
    <child link="left_front_thigh_spring"/>
    <origin rpy="0 1.570795 0" xyz="0 0 -0.05 "/>
    <axis rpy="0 0 0" xyz="0 1 0"/>
    <limit effort="1000" lower="-0.7853975" upper="0.7853975" velocity="100"/>
    <joint_properties damping="0.0" friction="0.0"/>
  </joint>
  <joint name="left_front_elastic_joint_thigh" type="revolute">
    <parent link="left_front_thigh_spring"/>
    <child link="left_front_thigh"/>
    <axis rpy="0 0 0" xyz="0 0 1">
      <dynamics>
        <spring_stiffness>10.0</spring_stiffness>
        <spring_reference>0</spring_reference>
      </dynamics>
    </axis>
    <limit effort="1000" lower="-0.0349065555556" upper="0.0349065555556" velocity="100"/>
  </joint>
  <transmission name="left_front_thigh_trans">
    <type>transmission_interface/SimpleTransmission</type>
    <joint name="left_front_thigh_hinge">
      <hardwareInterface>hardware_interface/EffortJointInterface</hardwareInterface>
    </joint>
    <actuator name="left_front_thigh_motor">
      <hardwareInterface>hardware_interface/EffortJointInterface</hardwareInterface>
      <mechanicalReduction>100</mechanicalReduction>
    </actuator>
  </transmission>
  <!-- A1 -->
  <joint name="left_front_calf_hinge" type="revolute">
    <parent link="left_front_thigh"/>
    <child link="left_front_calf_spring"/>
    <origin rpy="0 0 0" xyz="0.4 0 0"/>
    <axis rpy="0 0 0" xyz="0 1 0"/>
    <limit effort="1000" lower="0.7853975" upper="2.96705722222" velocity="100"/>
    <joint_properties damping="0.0" friction="0.0"/>
  </joint>
  <joint name="left_front_elastic_joint_calf" type="revolute">
    <parent link="left_front_calf_spring"/>
    <child link="left_front_calf"/>
    <axis rpy="0 0 0" xyz="0 0 1">
      <dynamics>
        <spring_stiffness>10.0</spring_stiffness>
        <spring_reference>0</spring_reference>
      </dynamics>
    </axis>
    <limit effort="1000" lower="-0.0349065555556" upper="0.0349065555556" velocity="100"/>
  </joint>
  <transmission name="left_front_calf_trans">
    <type>transmission_interface/SimpleTransmission</type>
    <joint name="left_front_calf_hinge">
      <hardwareInterface>hardware_interface/EffortJointInterface</hardwareInterface>
    </joint>
    <actuator name="left_front_calf_motor">
      <hardwareInterface>hardware_interface/EffortJointInterface</hardwareInterface>
      <mechanicalReduction>100</mechanicalReduction>
    </actuator>
  </transmission>
  <joint name="left_front_foot_hinge" type="fixed">
    <parent link="left_front_calf"/>
    <child link="left_front_foot"/>
    <origin rpy="0 0 0" xyz="0.3 0 0"/>
  </joint>
  <!-- close bracket -->
  <!-- create the shoulder -->
  <!-- link name="${lr}_${fr}_shoulder_spring"> 
    <inertial> <origin xyz="0 0 0" rpy="0 0 0"/> <mass value="1"/> <inertia ixx="1.0" ixy="0.0" ixz="0.0" iyy="1.0" iyz="0.0" izz="1.0"/> </inertial>
    </link-->
  <link name="left_rear_shoulder">
    <collision>
      <origin rpy="0 0 0" xyz="0 0 0"/>
      <geometry>
        <box size="0.1 0.1 0.1"/>
      </geometry>
    </collision>
    <visual>
      <origin rpy="0 1.570795 0" xyz="0 0 0"/>
      <geometry>
        <mesh filename="meshes/walking_base_v0/shoulder.stl">
                </mesh>
      </geometry>
      <material name="orange"/>
    </visual>
    <inertial>
      <origin rpy="0 0 0" xyz="0 0 0"/>
      <mass value="0.5"/>
      <inertia ixx="0.000833333333333" ixy="0" ixz="0" iyy="0.000833333333333" iyz="0" izz="0.000833333333333"/>
    </inertial>
  </link>
  <!-- create the thigh -->
  <link name="left_rear_thigh_spring">
    <!-- elastic joint -->
    <inertial>
      <origin rpy="0 0 0" xyz="0 0 0"/>
      <mass value="1"/>
      <inertia ixx="1.0" ixy="0.0" ixz="0.0" iyy="1.0" iyz="0.0" izz="1.0"/>
    </inertial>
  </link>
  <link name="left_rear_thigh">
    <collision>
      <origin rpy="0 1.570795 0" xyz="0.2 0 0"/>
      <geometry>
        <cylinder length="0.4" radius="0.04"/>
      </geometry>
    </collision>
    <visual>
      <origin rpy="0 1.570795 0" xyz="0 0 0"/>
      <geometry>
        <mesh filename="meshes/walking_base_v0/upper_leg.stl">
                </mesh>
      </geometry>
      <material name="orange"/>
    </visual>
    <inertial>
      <origin rpy="0 1.570795 0" xyz="0.2 0 0"/>
      <mass value="1.5"/>
      <inertia ixx="0.0206" ixy="0" ixz="0" iyy="0.0206" iyz="0" izz="0.0012"/>
    </inertial>
  </link>
  <!-- create the calf -->
  <link name="left_rear_calf_spring">
    <inertial>
      <origin rpy="0 0 0" xyz="0 0 0"/>
      <mass value="1"/>
      <inertia ixx="1.0" ixy="0.0" ixz="0.0" iyy="1.0" iyz="0.0" izz="1.0"/>
    </inertial>
  </link>
  <link name="left_rear_calf">
    <collision>
      <origin rpy="0 1.570795 0" xyz="0.15 0 0"/>
      <geometry>
        <cylinder length="0.3" radius="0.02"/>
      </geometry>
    </collision>
    <visual>
      <origin rpy="0 1.570795 0" xyz="0.15 0 0"/>
      <geometry>
        <mesh filename="meshes/walking_base_v0/lower_leg.stl">
                </mesh>
      </geometry>
    </visual>
    <inertial>
      <origin rpy="0 1.570795 0" xyz="0.15 0 0"/>
      <mass value="0.2"/>
      <inertia ixx="0.00152" ixy="0" ixz="0" iyy="0.00152" iyz="0" izz="4e-05"/>
    </inertial>
  </link>
  <!-- create the foot -->
  <link name="left_rear_foot">
    <collision>
      <origin rpy="0 0 0" xyz="0 0 0"/>
      <geometry>
        <sphere radius="0.05"/>
      </geometry>
      <surface>
        <friction>
          <ode>
            <mu>1</mu>
            <mu2>1</mu2>
            <slip1>1.0</slip1>
            <slip2>1.0</slip2>
          </ode>
        </friction>
      </surface>
    </collision>
    <inertial>
      <origin rpy="0 0 0" xyz="0 0 0"/>
      <mass value="0.1"/>
      <inertia ixx="0.0001" ixy="0" ixz="0" iyy="0.0001" iyz="0" izz="0.0001"/>
    </inertial>
  </link>
  <!-- hinges -->
  <!-- A3 -->
  <!--joint name="${lr}_${fr}_elastic_joint_shoulder" type="revolute">
        <parent link="${lr}_${fr}_shoulder_spring"/>
        <child link="${lr}_${fr}_shoulder"/>
        <axis xyz="1 0 0" rpy="0 0 0">
        <dynamics>
            <spring_stiffness>1000.0</spring_stiffness>
            <spring_reference>0</spring_reference>
        </dynamics>
        </axis>
        <limit effort="1000" velocity="100" upper="${A1_upper_rad}" lower="${A1_lower_rad}"/> 
    </joint-->
  <joint name="left_rear_shoulder_hinge" type="revolute">
    <parent link="chassis"/>
    <child link="left_rear_shoulder"/>
    <origin rpy="0 0 0" xyz="-0.25 0.15 0"/>
    <axis rpy="0 0 0" xyz="1 0 0"/>
    <limit effort="1000" lower="-0.174532777778" upper="0.7853975" velocity="100"/>
    <joint_properties damping="0.0" friction="0.0"/>
  </joint>
  <transmission name="left_rear_shoulder_trans">
    <type>transmission_interface/SimpleTransmission</type>
    <joint name="left_rear_shoulder_hinge">
      <hardwareInterface>hardware_interface/EffortJointInterface</hardwareInterface>
    </joint>
    <actuator name="left_rear_shoulder_motor">
      <hardwareInterface>hardware_interface/EffortJointInterface</hardwareInterface>
      <mechanicalReduction>100</mechanicalReduction>
    </actuator>
  </transmission>
  <!-- A2 -->
  <joint name="left_rear_thigh_hinge" type="revolute">
    <parent link="left_rear_shoulder"/>
    <child link="left_rear_thigh_spring"/>
    <origin rpy="0 1.570795 0" xyz="0 0 -0.05 "/>
    <axis rpy="0 0 0" xyz="0 1 0"/>
    <limit effort="1000" lower="-0.7853975" upper="0.7853975" velocity="100"/>
    <joint_properties damping="0.0" friction="0.0"/>
  </joint>
  <joint name="left_rear_elastic_joint_thigh" type="revolute">
    <parent link="left_rear_thigh_spring"/>
    <child link="left_rear_thigh"/>
    <axis rpy="0 0 0" xyz="0 0 1">
      <dynamics>
        <spring_stiffness>10.0</spring_stiffness>
        <spring_reference>0</spring_reference>
      </dynamics>
    </axis>
    <limit effort="1000" lower="-0.0349065555556" upper="0.0349065555556" velocity="100"/>
  </joint>
  <transmission name="left_rear_thigh_trans">
    <type>transmission_interface/SimpleTransmission</type>
    <joint name="left_rear_thigh_hinge">
      <hardwareInterface>hardware_interface/EffortJointInterface</hardwareInterface>
    </joint>
    <actuator name="left_rear_thigh_motor">
      <hardwareInterface>hardware_interface/EffortJointInterface</hardwareInterface>
      <mechanicalReduction>100</mechanicalReduction>
    </actuator>
  </transmission>
  <!-- A1 -->
  <joint name="left_rear_calf_hinge" type="revolute">
    <parent link="left_rear_thigh"/>
    <child link="left_rear_calf_spring"/>
    <origin rpy="0 0 0" xyz="0.4 0 0"/>
    <axis rpy="0 0 0" xyz="0 1 0"/>
    <limit effort="1000" lower="0.7853975" upper="2.96705722222" velocity="100"/>
    <joint_properties damping="0.0" friction="0.0"/>
  </joint>
  <joint name="left_rear_elastic_joint_calf" type="revolute">
    <parent link="left_rear_calf_spring"/>
    <child link="left_rear_calf"/>
    <axis rpy="0 0 0" xyz="0 0 1">
      <dynamics>
        <spring_stiffness>10.0</spring_stiffness>
        <spring_reference>0</spring_reference>
      </dynamics>
    </axis>
    <limit effort="1000" lower="-0.0349065555556" upper="0.0349065555556" velocity="100"/>
  </joint>
  <transmission name="left_rear_calf_trans">
    <type>transmission_interface/SimpleTransmission</type>
    <joint name="left_rear_calf_hinge">
      <hardwareInterface>hardware_interface/EffortJointInterface</hardwareInterface>
    </joint>
    <actuator name="left_rear_calf_motor">
      <hardwareInterface>hardware_interface/EffortJointInterface</hardwareInterface>
      <mechanicalReduction>100</mechanicalReduction>
    </actuator>
  </transmission>
  <joint name="left_rear_foot_hinge" type="fixed">
    <parent link="left_rear_calf"/>
    <child link="left_rear_foot"/>
    <origin rpy="0 0 0" xyz="0.3 0 0"/>
  </joint>
  <!-- close bracket -->
  <!-- create the shoulder -->
  <!-- link name="${lr}_${fr}_shoulder_spring"> 
    <inertial> <origin xyz="0 0 0" rpy="0 0 0"/> <mass value="1"/> <inertia ixx="1.0" ixy="0.0" ixz="0.0" iyy="1.0" iyz="0.0" izz="1.0"/> </inertial>
    </link-->
  <link name="right_front_shoulder">
    <collision>
      <origin rpy="0 0 0" xyz="0 0 0"/>
      <geometry>
        <box size="0.1 0.1 0.1"/>
      </geometry>
    </collision>
    <visual>
      <origin rpy="0 1.570795 0" xyz="0 0 0"/>
      <geometry>
        <mesh filename="meshes/walking_base_v0/shoulder.stl">
                </mesh>
      </geometry>
      <material name="orange"/>
    </visual>
    <inertial>
      <origin rpy="0 0 0" xyz="0 0 0"/>
      <mass value="0.5"/>
      <inertia ixx="0.000833333333333" ixy="0" ixz="0" iyy="0.000833333333333" iyz="0" izz="0.000833333333333"/>
    </inertial>
  </link>
  <!-- create the thigh -->
  <link name="right_front_thigh_spring">
    <!-- elastic joint -->
    <inertial>
      <origin rpy="0 0 0" xyz="0 0 0"/>
      <mass value="1"/>
      <inertia ixx="1.0" ixy="0.0" ixz="0.0" iyy="1.0" iyz="0.0" izz="1.0"/>
    </inertial>
  </link>
  <link name="right_front_thigh">
    <collision>
      <origin rpy="0 1.570795 0" xyz="0.2 0 0"/>
      <geometry>
        <cylinder length="0.4" radius="0.04"/>
      </geometry>
    </collision>
    <visual>
      <origin rpy="0 1.570795 0" xyz="0 0 0"/>
      <geometry>
        <mesh filename="meshes/walking_base_v0/upper_leg.stl">
                </mesh>
      </geometry>
      <material name="orange"/>
    </visual>
    <inertial>
      <origin rpy="0 1.570795 0" xyz="0.2 0 0"/>
      <mass value="1.5"/>
      <inertia ixx="0.0206" ixy="0" ixz="0" iyy="0.0206" iyz="0" izz="0.0012"/>
    </inertial>
  </link>
  <!-- create the calf -->
  <link name="right_front_calf_spring">
    <inertial>
      <origin rpy="0 0 0" xyz="0 0 0"/>
      <mass value="1"/>
      <inertia ixx="1.0" ixy="0.0" ixz="0.0" iyy="1.0" iyz="0.0" izz="1.0"/>
    </inertial>
  </link>
  <link name="right_front_calf">
    <collision>
      <origin rpy="0 1.570795 0" xyz="0.15 0 0"/>
      <geometry>
        <cylinder length="0.3" radius="0.02"/>
      </geometry>
    </collision>
    <visual>
      <origin rpy="0 1.570795 0" xyz="0.15 0 0"/>
      <geometry>
        <mesh filename="meshes/walking_base_v0/lower_leg.stl">
                </mesh>
      </geometry>
    </visual>
    <inertial>
      <origin rpy="0 1.570795 0" xyz="0.15 0 0"/>
      <mass value="0.2"/>
      <inertia ixx="0.00152" ixy="0" ixz="0" iyy="0.00152" iyz="0" izz="4e-05"/>
    </inertial>
  </link>
  <!-- create the foot -->
  <link name="right_front_foot">
    <collision>
      <origin rpy="0 0 0" xyz="0 0 0"/>
      <geometry>
        <sphere radius="0.05"/>
      </geometry>
      <surface>
        <friction>
          <ode>
            <mu>1</mu>
            <mu2>1</mu2>
            <slip1>1.0</slip1>
            <slip2>1.0</slip2>
          </ode>
        </friction>
      </surface>
    </collision>
    <inertial>
      <origin rpy="0 0 0" xyz="0 0 0"/>
      <mass value="0.1"/>
      <inertia ixx="0.0001" ixy="0" ixz="0" iyy="0.0001" iyz="0" izz="0.0001"/>
    </inertial>
  </link>
  <!-- hinges -->
  <!-- A3 -->
  <!--joint name="${lr}_${fr}_elastic_joint_shoulder" type="revolute">
        <parent link="${lr}_${fr}_shoulder_spring"/>
        <child link="${lr}_${fr}_shoulder"/>
        <axis xyz="1 0 0" rpy="0 0 0">
        <dynamics>
            <spring_stiffness>1000.0</spring_stiffness>
            <spring_reference>0</spring_reference>
        </dynamics>
        </axis>
        <limit effort="1000" velocity="100" upper="${A1_upper_rad}" lower="${A1_lower_rad}"/> 
    </joint-->
  <joint name="right_front_shoulder_hinge" type="revolute">
    <parent link="chassis"/>
    <child link="right_front_shoulder"/>
    <origin rpy="0 0 0" xyz="0.25 -0.15 0"/>
    <axis rpy="0 0 0" xyz="1 0 0"/>
    <limit effort="1000" lower="-0.7853975" upper="0.174532777778" velocity="100"/>
    <joint_properties damping="0.0" friction="0.0"/>
  </joint>
  <transmission name="right_front_shoulder_trans">
    <type>transmission_interface/SimpleTransmission</type>
    <joint name="right_front_shoulder_hinge">
      <hardwareInterface>hardware_interface/EffortJointInterface</hardwareInterface>
    </joint>
    <actuator name="right_front_shoulder_motor">
      <hardwareInterface>hardware_interface/EffortJointInterface</hardwareInterface>
      <mechanicalReduction>100</mechanicalReduction>
    </actuator>
  </transmission>
  <!-- A2 -->
  <joint name="right_front_thigh_hinge" type="revolute">
    <parent link="right_front_shoulder"/>
    <child link="right_front_thigh_spring"/>
    <origin rpy="0 1.570795 0" xyz="0 0 -0.05 "/>
    <axis rpy="0 0 0" xyz="0 1 0"/>
    <limit effort="1000" lower="-0.7853975" upper="0.7853975" velocity="100"/>
    <joint_properties damping="0.0" friction="0.0"/>
  </joint>
  <joint name="right_front_elastic_joint_thigh" type="revolute">
    <parent link="right_front_thigh_spring"/>
    <child link="right_front_thigh"/>
    <axis rpy="0 0 0" xyz="0 0 1">
      <dynamics>
        <spring_stiffness>10.0</spring_stiffness>
        <spring_reference>0</spring_reference>
      </dynamics>
    </axis>
    <limit effort="1000" lower="-0.0349065555556" upper="0.0349065555556" velocity="100"/>
  </joint>
  <transmission name="right_front_thigh_trans">
    <type>transmission_interface/SimpleTransmission</type>
    <joint name="right_front_thigh_hinge">
      <hardwareInterface>hardware_interface/EffortJointInterface</hardwareInterface>
    </joint>
    <actuator name="right_front_thigh_motor">
      <hardwareInterface>hardware_interface/EffortJointInterface</hardwareInterface>
      <mechanicalReduction>100</mechanicalReduction>
    </actuator>
  </transmission>
  <!-- A1 -->
  <joint name="right_front_calf_hinge" type="revolute">
    <parent link="right_front_thigh"/>
    <child link="right_front_calf_spring"/>
    <origin rpy="0 0 0" xyz="0.4 0 0"/>
    <axis rpy="0 0 0" xyz="0 1 0"/>
    <limit effort="1000" lower="0.7853975" upper="2.96705722222" velocity="100"/>
    <joint_properties damping="0.0" friction="0.0"/>
  </joint>
  <joint name="right_front_elastic_joint_calf" type="revolute">
    <parent link="right_front_calf_spring"/>
    <child link="right_front_calf"/>
    <axis rpy="0 0 0" xyz="0 0 1">
      <dynamics>
        <spring_stiffness>10.0</spring_stiffness>
        <spring_reference>0</spring_reference>
      </dynamics>
    </axis>
    <limit effort="1000" lower="-0.0349065555556" upper="0.0349065555556" velocity="100"/>
  </joint>
  <transmission name="right_front_calf_trans">
    <type>transmission_interface/SimpleTransmission</type>
    <joint name="right_front_calf_hinge">
      <hardwareInterface>hardware_interface/EffortJointInterface</hardwareInterface>
    </joint>
    <actuator name="right_front_calf_motor">
      <hardwareInterface>hardware_interface/EffortJointInterface</hardwareInterface>
      <mechanicalReduction>100</mechanicalReduction>
    </actuator>
  </transmission>
  <joint name="right_front_foot_hinge" type="fixed">
    <parent link="right_front_calf"/>
    <child link="right_front_foot"/>
    <origin rpy="0 0 0" xyz="0.3 0 0"/>
  </joint>
  <!-- close bracket -->
  <!-- create the shoulder -->
  <!-- link name="${lr}_${fr}_shoulder_spring"> 
    <inertial> <origin xyz="0 0 0" rpy="0 0 0"/> <mass value="1"/> <inertia ixx="1.0" ixy="0.0" ixz="0.0" iyy="1.0" iyz="0.0" izz="1.0"/> </inertial>
    </link-->
  <link name="right_rear_shoulder">
    <collision>
      <origin rpy="0 0 0" xyz="0 0 0"/>
      <geometry>
        <box size="0.1 0.1 0.1"/>
      </geometry>
    </collision>
    <visual>
      <origin rpy="0 1.570795 0" xyz="0 0 0"/>
      <geometry>
        <mesh filename="meshes/walking_base_v0/shoulder.stl">
                </mesh>
      </geometry>
      <material name="orange"/>
    </visual>
    <inertial>
      <origin rpy="0 0 0" xyz="0 0 0"/>
      <mass value="0.5"/>
      <inertia ixx="0.000833333333333" ixy="0" ixz="0" iyy="0.000833333333333" iyz="0" izz="0.000833333333333"/>
    </inertial>
  </link>
  <!-- create the thigh -->
  <link name="right_rear_thigh_spring">
    <!-- elastic joint -->
    <inertial>
      <origin rpy="0 0 0" xyz="0 0 0"/>
      <mass value="1"/>
      <inertia ixx="1.0" ixy="0.0" ixz="0.0" iyy="1.0" iyz="0.0" izz="1.0"/>
    </inertial>
  </link>
  <link name="right_rear_thigh">
    <collision>
      <origin rpy="0 1.570795 0" xyz="0.2 0 0"/>
      <geometry>
        <cylinder length="0.4" radius="0.04"/>
      </geometry>
    </collision>
    <visual>
      <origin rpy="0 1.570795 0" xyz="0 0 0"/>
      <geometry>
        <mesh filename="meshes/walking_base_v0/upper_leg.stl">
                </mesh>
      </geometry>
      <material name="orange"/>
    </visual>
    <inertial>
      <origin rpy="0 1.570795 0" xyz="0.2 0 0"/>
      <mass value="1.5"/>
      <inertia ixx="0.0206" ixy="0" ixz="0" iyy="0.0206" iyz="0" izz="0.0012"/>
    </inertial>
  </link>
  <!-- create the calf -->
  <link name="right_rear_calf_spring">
    <inertial>
      <origin rpy="0 0 0" xyz="0 0 0"/>
      <mass value="1"/>
      <inertia ixx="1.0" ixy="0.0" ixz="0.0" iyy="1.0" iyz="0.0" izz="1.0"/>
    </inertial>
  </link>
  <link name="right_rear_calf">
    <collision>
      <origin rpy="0 1.570795 0" xyz="0.15 0 0"/>
      <geometry>
        <cylinder length="0.3" radius="0.02"/>
      </geometry>
    </collision>
    <visual>
      <origin rpy="0 1.570795 0" xyz="0.15 0 0"/>
      <geometry>
        <mesh filename="meshes/walking_base_v0/lower_leg.stl">
                </mesh>
      </geometry>
    </visual>
    <inertial>
      <origin rpy="0 1.570795 0" xyz="0.15 0 0"/>
      <mass value="0.2"/>
      <inertia ixx="0.00152" ixy="0" ixz="0" iyy="0.00152" iyz="0" izz="4e-05"/>
    </inertial>
  </link>
  <!-- create the foot -->
  <link name="right_rear_foot">
    <collision>
      <origin rpy="0 0 0" xyz="0 0 0"/>
      <geometry>
        <sphere radius="0.05"/>
      </geometry>
      <surface>
        <friction>
          <ode>
            <mu>1</mu>
            <mu2>1</mu2>
            <slip1>1.0</slip1>
            <slip2>1.0</slip2>
          </ode>
        </friction>
      </surface>
    </collision>
    <inertial>
      <origin rpy="0 0 0" xyz="0 0 0"/>
      <mass value="0.1"/>
      <inertia ixx="0.0001" ixy="0" ixz="0" iyy="0.0001" iyz="0" izz="0.0001"/>
    </inertial>
  </link>
  <!-- hinges -->
  <!-- A3 -->
  <!--joint name="${lr}_${fr}_elastic_joint_shoulder" type="revolute">
        <parent link="${lr}_${fr}_shoulder_spring"/>
        <child link="${lr}_${fr}_shoulder"/>
        <axis xyz="1 0 0" rpy="0 0 0">
        <dynamics>
            <spring_stiffness>1000.0</spring_stiffness>
            <spring_reference>0</spring_reference>
        </dynamics>
        </axis>
        <limit effort="1000" velocity="100" upper="${A1_upper_rad}" lower="${A1_lower_rad}"/> 
    </joint-->
  <joint name="right_rear_shoulder_hinge" type="revolute">
    <parent link="chassis"/>
    <child link="right_rear_shoulder"/>
    <origin rpy="0 0 0" xyz="-0.25 -0.15 0"/>
    <axis rpy="0 0 0" xyz="1 0 0"/>
    <limit effort="1000" lower="-0.7853975" upper="0.174532777778" velocity="100"/>
    <joint_properties damping="0.0" friction="0.0"/>
  </joint>
  <transmission name="right_rear_shoulder_trans">
    <type>transmission_interface/SimpleTransmission</type>
    <joint name="right_rear_shoulder_hinge">
      <hardwareInterface>hardware_interface/EffortJointInterface</hardwareInterface>
    </joint>
    <actuator name="right_rear_shoulder_motor">
      <hardwareInterface>hardware_interface/EffortJointInterface</hardwareInterface>
      <mechanicalReduction>100</mechanicalReduction>
    </actuator>
  </transmission>
  <!-- A2 -->
  <joint name="right_rear_thigh_hinge" type="revolute">
    <parent link="right_rear_shoulder"/>
    <child link="right_rear_thigh_spring"/>
    <origin rpy="0 1.570795 0" xyz="0 0 -0.05 "/>
    <axis rpy="0 0 0" xyz="0 1 0"/>
    <limit effort="1000" lower="-0.7853975" upper="0.7853975" velocity="100"/>
    <joint_properties damping="0.0" friction="0.0"/>
  </joint>
  <joint name="right_rear_elastic_joint_thigh" type="revolute">
    <parent link="right_rear_thigh_spring"/>
    <child link="right_rear_thigh"/>
    <axis rpy="0 0 0" xyz="0 0 1">
      <dynamics>
        <spring_stiffness>10.0</spring_stiffness>
        <spring_reference>0</spring_reference>
      </dynamics>
    </axis>
    <limit effort="1000" lower="-0.0349065555556" upper="0.0349065555556" velocity="100"/>
  </joint>
  <transmission name="right_rear_thigh_trans">
    <type>transmission_interface/SimpleTransmission</type>
    <joint name="right_rear_thigh_hinge">
      <hardwareInterface>hardware_interface/EffortJointInterface</hardwareInterface>
    </joint>
    <actuator name="right_rear_thigh_motor">
      <hardwareInterface>hardware_interface/EffortJointInterface</hardwareInterface>
      <mechanicalReduction>100</mechanicalReduction>
    </actuator>
  </transmission>
  <!-- A1 -->
  <joint name="right_rear_calf_hinge" type="revolute">
    <parent link="right_rear_thigh"/>
    <child link="right_rear_calf_spring"/>
    <origin rpy="0 0 0" xyz="0.4 0 0"/>
    <axis rpy="0 0 0" xyz="0 1 0"/>
    <limit effort="1000" lower="0.7853975" upper="2.96705722222" velocity="100"/>
    <joint_properties damping="0.0" friction="0.0"/>
  </joint>
  <joint name="right_rear_elastic_joint_calf" type="revolute">
    <parent link="right_rear_calf_spring"/>
    <child link="right_rear_calf"/>
    <axis rpy="0 0 0" xyz="0 0 1">
      <dynamics>
        <spring_stiffness>10.0</spring_stiffness>
        <spring_reference>0</spring_reference>
      </dynamics>
    </axis>
    <limit effort="1000" lower="-0.0349065555556" upper="0.0349065555556" velocity="100"/>
  </joint>
  <transmission name="right_rear_calf_trans">
    <type>transmission_interface/SimpleTransmission</type>
    <joint name="right_rear_calf_hinge">
      <hardwareInterface>hardware_interface/EffortJointInterface</hardwareInterface>
    </joint>
    <actuator name="right_rear_calf_motor">
      <hardwareInterface>hardware_interface/EffortJointInterface</hardwareInterface>
      <mechanicalReduction>100</mechanicalReduction>
    </actuator>
  </transmission>
  <joint name="right_rear_foot_hinge" type="fixed">
    <parent link="right_rear_calf"/>
    <child link="right_rear_foot"/>
    <origin rpy="0 0 0" xyz="0.3 0 0"/>
  </joint>
  <!-- close bracket -->
  <!-- camera -->
  <gazebo reference="asus_camera_link">
    <sensor name="camera" type="depth">
      <always_on>true</always_on>
      <update_rate>10.0</update_rate>
      <camera>
        <horizontal_fov>1.0471975512</horizontal_fov>
        <image>
          <format>R8G8B8</format>
          <width>640</width>
          <height>480</height>
        </image>
        <clip>
          <near>0.05</near>
          <far>8.0</far>
        </clip>
      </camera>
      <plugin filename="libgazebo_ros_openni_kinect.so" name="kinect_camera_controller">
        <cameraName>nav_module/asus_camera</cameraName>
        <alwaysOn>true</alwaysOn>
        <updateRate>10</updateRate>
        <imageTopicName>rgb/image_raw</imageTopicName>
        <depthImageTopicName>depth/image_raw</depthImageTopicName>
        <pointCloudTopicName>depth/points</pointCloudTopicName>
        <cameraInfoTopicName>rgb/camera_info</cameraInfoTopicName>
        <depthImageCameraInfoTopicName>depth/camera_info</depthImageCameraInfoTopicName>
        <frameName>asus_camera_link_optical</frameName>
        <baseline>0.1</baseline>
        <distortion_k1>0.0</distortion_k1>
        <distortion_k2>0.0</distortion_k2>
        <distortion_k3>0.0</distortion_k3>
        <distortion_t1>0.0</distortion_t1>
        <distortion_t2>0.0</distortion_t2>
        <pointCloudCutoff>0.4</pointCloudCutoff>
      </plugin>
    </sensor>
  </gazebo>
  <!-- name of square 'camera' box -->
  <!-- lidar -->
  <gazebo reference="base_laser">
    <material>Gazebo/Blue</material>
    <turnGravityOff>false</turnGravityOff>
    <sensor name="lidar2d_sensor" type="ray">
      <pose>0.025 0 0 0 0 0</pose>
      <visualize>false</visualize>
      <update_rate>40</update_rate>
      <ray>
        <scan>
          <horizontal>
            <samples>720</samples>
            <resolution>1</resolution>
            <min_angle>-1.570796</min_angle>
            <max_angle>1.570796</max_angle>
          </horizontal>
        </scan>
        <range>
          <min>0.10</min>
          <max>10.0</max>
          <resolution>0.001</resolution>
        </range>
      </ray>
      <plugin filename="libgazebo_ros_laser.so" name="lidar2d_controller">
        <topicName>nav_module/scan</topicName>
        <frameName>base_laser</frameName>
        <!-- needs to be base_laser for navigation stack -->
      </plugin>
    </sensor>
  </gazebo>
  <gazebo>
    <plugin filename="libgazebo_ros_imu.so" name="imu_plugin">
      <alwaysOn>true</alwaysOn>
      <bodyName>imu_link</bodyName>
      <topicName>aida/imu_data</topicName>
      <serviceName>imu_service</serviceName>
      <gaussianNoise>2.89e-08</gaussianNoise>
      <updateRate>10.0</updateRate>
    </plugin>
  </gazebo>
  <link name="base_link"/>
  <joint name="base_joint" type="fixed">
    <parent link="base_link"/>
    <child link="chassis"/>
  </joint>
  <!-- add the navigation module -->
  <!--fb : front, back ; lr: left, right -->
  <!-- params 
     x_rgbcamera : x dispalcement of the cameras to the back.
     y_rgvcamera : y displacement of the cameras on the sides ( 2 cameras )-->
  <!-- define here all the sensors and elements related to te head of the robot -->
  <link name="nav_module_link"/>
  <!-- SENSOR links -->
  <!-- lidar2d -->
  <link name="base_laser">
    <visual>
      <origin rpy="0 0 0" xyz="0 0 0"/>
      <geometry>
        <box size="0.05 0.05 0.05"/>
      </geometry>
      <material name="Blue"/>
    </visual>
  </link>
  <joint name="lidar2d_joint" type="fixed">
    <origin rpy="0 0 1.57079632679" xyz="0.125 0 0.0125"/>
    <parent link="nav_module_link"/>
    <child link="base_laser"/>
  </joint>
  <!-- Asus Camera -->
  <joint name="asus_camera_joint" type="fixed">
    <axis rpy="0 0 0" xyz="1 0 0."/>
    <origin rpy="0 0 0" xyz="0.125 0 0.075"/>
    <parent link="nav_module_link"/>
    <child link="asus_camera_link"/>
  </joint>
  <link name="asus_camera_link"/>
  <link name="asus_camera_link_optical"/>
  <joint name="asus_camera_optical_joint" type="fixed">
    <!-- these values have to be these values otherwise the gazebo camera
      image won't be aligned properly with the frame it is supposedly
      originating from -->
    <origin rpy="-1.57079632679 0 -1.57079632679" xyz="0 0 0"/>
    <parent link="asus_camera_link"/>
    <child link="asus_camera_link_optical"/>
  </joint>
  <!--fb : front, back ; lr: left, right -->
  <!-- camera -->
  <gazebo reference="rgb_cam_rl_link">
    <material>Gazebo/Blue</material>
    <sensor name="camera" type="camera">
      <update_rate>30.0</update_rate>
      <camera name="head">
        <horizontal_fov>1.3962634</horizontal_fov>
        <image>
          <width>800</width>
          <height>800</height>
          <format>R8G8B8</format>
        </image>
        <clip>
          <near>0.02</near>
          <far>300</far>
        </clip>
      </camera>
      <plugin filename="libgazebo_ros_camera.so" name="camera_controller">
        <alwaysOn>true</alwaysOn>
        <updateRate>0.0</updateRate>
        <cameraName>nav_module/rgb_cam_rl</cameraName>
        <imageTopicName>image_raw</imageTopicName>
        <cameraInfoTopicName>camera_info</cameraInfoTopicName>
        <frameName>camera_link</frameName>
        <hackBaseline>0.07</hackBaseline>
        <distortionK1>0.0</distortionK1>
        <distortionK2>0.0</distortionK2>
        <distortionK3>0.0</distortionK3>
        <distortionT1>0.0</distortionT1>
        <distortionT2>0.0</distortionT2>
      </plugin>
    </sensor>
  </gazebo>
  <!--fb : front, back ; lr: left, right -->
  <!-- camera -->
  <gazebo reference="rgb_cam_rr_link">
    <material>Gazebo/Blue</material>
    <sensor name="camera" type="camera">
      <update_rate>30.0</update_rate>
      <camera name="head">
        <horizontal_fov>1.3962634</horizontal_fov>
        <image>
          <width>800</width>
          <height>800</height>
          <format>R8G8B8</format>
        </image>
        <clip>
          <near>0.02</near>
          <far>300</far>
        </clip>
      </camera>
      <plugin filename="libgazebo_ros_camera.so" name="camera_controller">
        <alwaysOn>true</alwaysOn>
        <updateRate>0.0</updateRate>
        <cameraName>nav_module/rgb_cam_rr</cameraName>
        <imageTopicName>image_raw</imageTopicName>
        <cameraInfoTopicName>camera_info</cameraInfoTopicName>
        <frameName>camera_link</frameName>
        <hackBaseline>0.07</hackBaseline>
        <distortionK1>0.0</distortionK1>
        <distortionK2>0.0</distortionK2>
        <distortionK3>0.0</distortionK3>
        <distortionT1>0.0</distortionT1>
        <distortionT2>0.0</distortionT2>
      </plugin>
    </sensor>
  </gazebo>
  <link name="rgb_cam_rl_link"/>
  <link name="rgb_cam_rr_link"/>
  <joint name="rgb_cam_rl_joint" type="fixed">
    <origin rpy="0 0 2.35619449019" xyz="-0.15 0.1 0"/>
    <parent link="nav_module_link"/>
    <child link="rgb_cam_rl_link"/>
  </joint>
  <joint name="rgb_cam_rr_joint" type="fixed">
    <origin rpy="0 0 -2.35619449019" xyz="-0.15 -0.1 0"/>
    <parent link="nav_module_link"/>
    <child link="rgb_cam_rr_link"/>
  </joint>
  <link name="imu_link">
    <inertial>
      <mass value="0.01"/>
      <origin xyz="0 0 0"/>
      <inertia ixx="0.001" ixy="0.0" ixz="0.0" iyy="0.001" iyz="0.0" izz="0.001"/>
    </inertial>
    <visual>
      <origin rpy="0 0 0" xyz="0 0 0"/>
      <geometry>
        <box size="0.03 0.03 0.03"/>
      </geometry>
    </visual>
  </link>
  <joint name="imu_joint" type="fixed">
    <axis xyz="0 0 0"/>
    <origin rpy="0 0 0" xyz="0. 0. 0.1"/>
    <parent link="chassis"/>
    <child link="imu_link"/>
  </joint>
  <joint name="nav_module_joint" type="fixed">
    <parent link="base_link"/>
    <child link="nav_module_link"/>
    <origin rpy="0 0 0" xyz="0.1 0 0.25"/>
  </joint>
</robot>
